/usr/local/lib/python3.8/site-packages/django/utils/log.py Thread-1 log log_response Internal Server Error: /run/
Traceback (most recent call last):
  File "/usr/local/lib/python3.8/site-packages/django/core/handlers/exception.py", line 47, in inner
    response = get_response(request)
  File "/usr/local/lib/python3.8/site-packages/django/core/handlers/base.py", line 181, in _get_response
    response = wrapped_callback(request, *callback_args, **callback_kwargs)
  File "/usr/local/lib/python3.8/site-packages/django/views/decorators/csrf.py", line 54, in wrapped_view
    return view_func(*args, **kwargs)
  File "/usr/local/lib/python3.8/site-packages/django/views/generic/base.py", line 70, in view
    return self.dispatch(request, *args, **kwargs)
  File "/usr/local/lib/python3.8/site-packages/rest_framework/views.py", line 509, in dispatch
    response = self.handle_exception(exc)
  File "/usr/local/lib/python3.8/site-packages/rest_framework/views.py", line 469, in handle_exception
    self.raise_uncaught_exception(exc)
  File "/usr/local/lib/python3.8/site-packages/rest_framework/views.py", line 480, in raise_uncaught_exception
    raise exc
  File "/usr/local/lib/python3.8/site-packages/rest_framework/views.py", line 506, in dispatch
    response = handler(request, *args, **kwargs)
  File "/code/web/main/views.py", line 93, in post
    results = ip2(input_messages,ids,appSettings["num_check_bits"],appSettings["num_decoy"])
  File "/code/web/main/simulator/topology_funcs.py", line 441, in ip2
    results=ip2_run(topology,input_messages,ids,num_check_bits,num_decoy)
  File "/code/web/main/simulator/app/ip2.py", line 175, in ip2_run
    network = Network(topology=topology, messages=messages, size=lambda x: x//2+len(ids[1]), label='00')
  File "/usr/local/lib/python3.8/site-packages/qntsim/library/network.py", line 48, in __init__
    self.__initiate__()
  File "/usr/local/lib/python3.8/site-packages/qntsim/library/network.py", line 72, in __initiate__
    self.__request_entanglements__()
  File "/usr/local/lib/python3.8/site-packages/qntsim/library/network.py", line 105, in __request_entanglements__
    for k1, k2 in zip(keys[:-1], keys[1:]):
TypeError: 'int' object is not subscriptable
/usr/local/lib/python3.8/site-packages/django/utils/autoreload.py MainThread autoreload trigger_reload /code/web/main/simulator/app/ip2.py changed, reloading.
